Workbook

Sheet ali
A1: NAME | B1: STOCK QYT | I1: TYPE
A2: {=_xlfn._xlws.FILTER(STOCK!C:C,(STOCK!A:A=I2)+(STOCK!A:A=I3))} -> RC 5 | B2: =IFERROR(VLOOKUP(A2,STOCK!C:F,4,FALSE),"") -> 9871 | I2: RC
A3: RC 10 | B3: =IFERROR(VLOOKUP(A3,STOCK!C:F,4,FALSE),"") -> 8478 | I3: MVD
A4: RC 50 | B4: =IFERROR(VLOOKUP(A4,STOCK!C:F,4,FALSE),"") -> 40
A5: RC 10G New | B5: =IFERROR(VLOOKUP(A5,STOCK!C:F,4,FALSE),"") -> 25
A6: RC 15 | B6: =IFERROR(VLOOKUP(A6,STOCK!C:F,4,FALSE),"") -> 404
A7: RCBNDL25K | B7: =IFERROR(VLOOKUP(A7,STOCK!C:F,4,FALSE),"") -> 784
A8: RCBNDL35K | B8: =IFERROR(VLOOKUP(A8,STOCK!C:F,4,FALSE),"") -> 331
A9: RC 5G New | B9: =IFERROR(VLOOKUP(A9,STOCK!C:F,4,FALSE),"") -> 60
A10: RC 25 | B10: =IFERROR(VLOOKUP(A10,STOCK!C:F,4,FALSE),"") -> 225
A11: RCBNDL50K | B11: =IFERROR(VLOOKUP(A11,STOCK!C:F,4,FALSE),"") -> 27
A12: RCBNDL12K | B12: =IFERROR(VLOOKUP(A12,STOCK!C:F,4,FALSE),"") -> 12
A13: MVD | B13: =IFERROR(VLOOKUP(A13,STOCK!C:F,4,FALSE),"") -> 22820
A14: RC 35 | B14: =IFERROR(VLOOKUP(A14,STOCK!C:F,4,FALSE),"") -> 265
A15: RC100 | B15: =IFERROR(VLOOKUP(A15,STOCK!C:F,4,FALSE),"") -> 79
B16: =IFERROR(VLOOKUP(A16,STOCK!C:F,4,FALSE),"")
B17: =IFERROR(VLOOKUP(A17,STOCK!C:F,4,FALSE),"")
B18: =IFERROR(VLOOKUP(A18,STOCK!C:F,4,FALSE),"")
B19: =IFERROR(VLOOKUP(A19,STOCK!C:F,4,FALSE),"")
B20: =IFERROR(VLOOKUP(A20,STOCK!C:F,4,FALSE),"")
B21: =IFERROR(VLOOKUP(A21,STOCK!C:F,4,FALSE),"")
B22: =IFERROR(VLOOKUP(A22,STOCK!C:F,4,FALSE),"")
B23: =IFERROR(VLOOKUP(A23,STOCK!C:F,4,FALSE),"")
B24: =IFERROR(VLOOKUP(A24,STOCK!C:F,4,FALSE),"")
B25: =IFERROR(VLOOKUP(A25,STOCK!C:F,4,FALSE),"")
B26: =IFERROR(VLOOKUP(A26,STOCK!C:F,4,FALSE),"")
B27: =IFERROR(VLOOKUP(A27,STOCK!C:F,4,FALSE),"")
... B100: =IFERROR(VLOOKUP(A100,STOCK!C:F,4,FALSE),"")

Sheet omer
A1: NAME | B1: STOCK QYT | J1: TYPE
A2: {=_xlfn._xlws.FILTER(STOCK!C:C,STOCK!A:A=omer!J2)} -> RES1-WFM026TSIM3000 | B2: =IFERROR(VLOOKUP(A2,STOCK!C:F,4,FALSE),"") -> 15 | J2: WIFI
A3: ZAINFi2SIM | B3: =IFERROR(VLOOKUP(A3,STOCK!C:F,4,FALSE),"") -> 122
A4: ZF2B535-235ASIM | B4: =IFERROR(VLOOKUP(A4,STOCK!C:F,4,FALSE),"") -> 146
A5: RES2-WLTSLT718 | B5: =IFERROR(VLOOKUP(A5,STOCK!C:F,4,FALSE),"") -> 33
A6: ZF1E5783-230ASIM3000 | B6: =IFERROR(VLOOKUP(A6,STOCK!C:F,4,FALSE),"") -> 24
A7: WIFSIMM022T | B7: =IFERROR(VLOOKUP(A7,STOCK!C:F,4,FALSE),"") -> 192
A8: RES2-ZF2B535-235ASIM | B8: =IFERROR(VLOOKUP(A8,STOCK!C:F,4,FALSE),"") -> 28
A9: RES-WLTSLT718 | B9: =IFERROR(VLOOKUP(A9,STOCK!C:F,4,FALSE),"") -> 54
B10: =IFERROR(VLOOKUP(A10,STOCK!C:F,4,FALSE),"")
B11: =IFERROR(VLOOKUP(A11,STOCK!C:F,4,FALSE),"")
B12: =IFERROR(VLOOKUP(A12,STOCK!C:F,4,FALSE),"")
B13: =IFERROR(VLOOKUP(A13,STOCK!C:F,4,FALSE),"")
B14: =IFERROR(VLOOKUP(A14,STOCK!C:F,4,FALSE),"")
B15: =IFERROR(VLOOKUP(A15,STOCK!C:F,4,FALSE),"")
B16: =IFERROR(VLOOKUP(A16,STOCK!C:F,4,FALSE),"")
B17: =IFERROR(VLOOKUP(A17,STOCK!C:F,4,FALSE),"")
B18: =IFERROR(VLOOKUP(A18,STOCK!C:F,4,FALSE),"")
B19: =IFERROR(VLOOKUP(A19,STOCK!C:F,4,FALSE),"")
B20: =IFERROR(VLOOKUP(A20,STOCK!C:F,4,FALSE),"")
B21: =IFERROR(VLOOKUP(A21,STOCK!C:F,4,FALSE),"")
... B100: =IFERROR(VLOOKUP(A100,STOCK!C:F,4,FALSE),"")

Sheet karar
A1: NAME | B1: STOCK QYT | J1: TYPE
A2: {=_xlfn._xlws.FILTER(STOCK!C:C,(STOCK!A:A=J2)+(STOCK!A:A=karar!J3))} -> ZCNCT3PACK | B2: =IFERROR(VLOOKUP(A2,STOCK!C:F,4,FALSE),"") -> 1537 | J2: SIM
A3: QRESIM | B3: =IFERROR(VLOOKUP(A3,STOCK!C:F,4,FALSE),"") -> 30 | J3: Device
A4: EZINF2PPPACK | B4: =IFERROR(VLOOKUP(A4,STOCK!C:F,4,FALSE),"") -> 44
A5: EZINF2GPPACK | B5: =IFERROR(VLOOKUP(A5,STOCK!C:F,4,FALSE),"") -> 7
A6: SIMSWAP | B6: =IFERROR(VLOOKUP(A6,STOCK!C:F,4,FALSE),"") -> 1096
A7: FINGER PRINT | B7: =IFERROR(VLOOKUP(A7,STOCK!C:F,4,FALSE),"") -> 38
A8: ZCNCTRES2SIM | B8: =IFERROR(VLOOKUP(A8,STOCK!C:F,4,FALSE),"") -> 47
A9: ZYARADATA3PACK | B9: =IFERROR(VLOOKUP(A9,STOCK!C:F,4,FALSE),"") -> 6377
A10: EZINF2DPACK | B10: =IFERROR(VLOOKUP(A10,STOCK!C:F,4,FALSE),"") -> 1
A11: EZYARA15KPACK | B11: =IFERROR(VLOOKUP(A11,STOCK!C:F,4,FALSE),"") -> 6490
A12: PHONE | B12: =IFERROR(VLOOKUP(A12,STOCK!C:F,4,FALSE),"") -> 79
A13: ZAINFLEXPACK | B13: =IFERROR(VLOOKUP(A13,STOCK!C:F,4,FALSE),"") -> 41967
A14: ORYXSIM | B14: =IFERROR(VLOOKUP(A14,STOCK!C:F,4,FALSE),"") -> 666
A15: MFES | B15: =IFERROR(VLOOKUP(A15,STOCK!C:F,4,FALSE),"") -> 32
... A30: Zain Prime | B30: =IFERROR(VLOOKUP(A30,STOCK!C:F,4,FALSE),"") -> 109
B31: =IFERROR(VLOOKUP(A31,STOCK!C:F,4,FALSE),"")
B32: =IFERROR(VLOOKUP(A32,STOCK!C:F,4,FALSE),"")
B33: =IFERROR(VLOOKUP(A33,STOCK!C:F,4,FALSE),"")
B34: =IFERROR(VLOOKUP(A34,STOCK!C:F,4,FALSE),"")
B35: =IFERROR(VLOOKUP(A35,STOCK!C:F,4,FALSE),"")
B36: =IFERROR(VLOOKUP(A36,STOCK!C:F,4,FALSE),"")
B37: =IFERROR(VLOOKUP(A37,STOCK!C:F,4,FALSE),"")
B38: =IFERROR(VLOOKUP(A38,STOCK!C:F,4,FALSE),"")
B39: =IFERROR(VLOOKUP(A39,STOCK!C:F,4,FALSE),"")
B40: =IFERROR(VLOOKUP(A40,STOCK!C:F,4,FALSE),"")
B41: =IFERROR(VLOOKUP(A41,STOCK!C:F,4,FALSE),"")
B42: =IFERROR(VLOOKUP(A42,STOCK!C:F,4,FALSE),"")
... B100: =IFERROR(VLOOKUP(A100,STOCK!C:F,4,FALSE),"")

Sheet STOCK
A1: TYPE | C1: NAEM | F1: QYT
A2: SIM | B2: ST-030054 | C2: ZCNCT3PACK | F2: 1537
A3: iTunes | B3: ST-11-01-0006 | C3: iTunes (US) $50 | F3: 1
A4: Yalla Ludo | B4: ST-240008 | C4: Yalla Ludo 2333 Diamonds | F4: 20
A5: SIM | B5: ST-030075 | C5: QRESIM | F5: 30
A6: Razer gold | B6: ST-15-01-0002 | C6: Razer$10 Voucher | F6: 2
A7: EVD | B7: ST-020044 | C7: EVD 3000 | F7: 5690
A8: iTunes | B8: ST-11-01-0009 | C8: iTunes $2 | F8: 13
A9: EVD | B9: ST-020056 | C9: EVDNITRO50K_250G | F9: 60
A10: iTunes | B10: ST-11-01-0011 | C10: iTunes $4 | F10: 20
A11: WIFI | B11: ST-060011 | C11: RES1-WFM026TSIM3000 | F11: 15
A12: iTunes | B12: ST-11-01-0008 | C12: iTunes (US) $200 | F12: 1
A13: PUBG Pins | B13: ST-14-01-0001 | C13: 60 UC | F13: 125
... A118: SIM | B118: ST-030041 | C118: Zain Prime | F118: 109
A119: Total | F119: 349123
A120: VSALAMPACK | B120: SIM
A121: HZ3DPPACK | B121: SIM
A122: EZINF2SPPACK | B122: SIM
A123: VS3ALAMPACK | B123: SIM
A124: VS2ALAMPACK | B124: SIM
A125: FZINF2 VG PACK 75000 | B125: SIM
A126: VSZORPACK | B126: SIM
A127: EZALAM2PACK | B127: SIM
A128: HZ3VCNTPACK | B128: SIM
A129: ZYARA2_5GPACK | B129: SIM
A130: ZCNCTRES1SIM | B130: SIM | C130: 140
A131: ZCNCTRES2SIM | B131: SIM | C131: 47
A132: ZCNCT3PACK | B132: SIM | C132: 1540
A133: EZYARA10KPACK | B133: SIM
A134: EZYARA15KPACK | B134: SIM | C134: 6490
A135: EZYARA20KPACK | B135: SIM
A136: QR-ORYXESIM | B136: SIM
A137: RZYARADATA1PACK | B137: SIM | C137: 4132
A138: RZYARADATA2PACK | B138: SIM | C138: 7926
A139: ZYARADATA3PACK | B139: SIM | C139: 6377
A140: COMPZYARA1PACK | B140: SIM
A141: ULZYARADATA2PACK | B141: SIM
A142: ZAINFLEXPACK | B142: SIM | C142: 42815
A143: ZAINFLEXGPACK | B143: SIM
A144: ZAINFLEXGPPACK | B144: SIM
...
